2021-08-05 15:34:12,355 ERROR: Exception on /search [GET] [in d:\term\python_learn\microblog\venv\lib\site-packages\flask\app.py:1454]
Traceback (most recent call last):
  File "d:\term\python_learn\microblog\venv\lib\site-packages\urllib3\connection.py", line 169, in _new_conn
    conn = connection.create_connection(
  File "d:\term\python_learn\microblog\venv\lib\site-packages\urllib3\util\connection.py", line 96, in create_connection
    raise err
  File "d:\term\python_learn\microblog\venv\lib\site-packages\urllib3\util\connection.py", line 86, in create_connection
    sock.connect(sa)
ConnectionRefusedError: [WinError 10061] 由于目标计算机积极拒绝，无法连接。

During handling of the above exception, another exception occurred:

Traceback (most recent call last):
  File "d:\term\python_learn\microblog\venv\lib\site-packages\elasticsearch\connection\http_urllib3.py", line 251, in perform_request
    response = self.pool.urlopen(
  File "d:\term\python_learn\microblog\venv\lib\site-packages\urllib3\connectionpool.py", line 755, in urlopen
    retries = retries.increment(
  File "d:\term\python_learn\microblog\venv\lib\site-packages\urllib3\util\retry.py", line 507, in increment
    raise six.reraise(type(error), error, _stacktrace)
  File "d:\term\python_learn\microblog\venv\lib\site-packages\urllib3\packages\six.py", line 770, in reraise
    raise value
  File "d:\term\python_learn\microblog\venv\lib\site-packages\urllib3\connectionpool.py", line 699, in urlopen
    httplib_response = self._make_request(
  File "d:\term\python_learn\microblog\venv\lib\site-packages\urllib3\connectionpool.py", line 394, in _make_request
    conn.request(method, url, **httplib_request_kw)
  File "d:\term\python_learn\microblog\venv\lib\site-packages\urllib3\connection.py", line 234, in request
    super(HTTPConnection, self).request(method, url, body=body, headers=headers)
  File "C:\Users\14023\AppData\Local\Programs\Python\Python39\lib\http\client.py", line 1253, in request
    self._send_request(method, url, body, headers, encode_chunked)
  File "C:\Users\14023\AppData\Local\Programs\Python\Python39\lib\http\client.py", line 1299, in _send_request
    self.endheaders(body, encode_chunked=encode_chunked)
  File "C:\Users\14023\AppData\Local\Programs\Python\Python39\lib\http\client.py", line 1248, in endheaders
    self._send_output(message_body, encode_chunked=encode_chunked)
  File "C:\Users\14023\AppData\Local\Programs\Python\Python39\lib\http\client.py", line 1008, in _send_output
    self.send(msg)
  File "C:\Users\14023\AppData\Local\Programs\Python\Python39\lib\http\client.py", line 948, in send
    self.connect()
  File "d:\term\python_learn\microblog\venv\lib\site-packages\urllib3\connection.py", line 200, in connect
    conn = self._new_conn()
  File "d:\term\python_learn\microblog\venv\lib\site-packages\urllib3\connection.py", line 181, in _new_conn
    raise NewConnectionError(
urllib3.exceptions.NewConnectionError: <urllib3.connection.HTTPConnection object at 0x00000224A25FCBE0>: Failed to establish a new connection: [WinError 10061] 由于目标计算机积极拒绝，无法连接。

During handling of the above exception, another exception occurred:

Traceback (most recent call last):
  File "d:\term\python_learn\microblog\venv\lib\site-packages\flask\app.py", line 2070, in wsgi_app
    response = self.full_dispatch_request()
  File "d:\term\python_learn\microblog\venv\lib\site-packages\flask\app.py", line 1515, in full_dispatch_request
    rv = self.handle_user_exception(e)
  File "d:\term\python_learn\microblog\venv\lib\site-packages\flask\app.py", line 1513, in full_dispatch_request
    rv = self.dispatch_request()
  File "d:\term\python_learn\microblog\venv\lib\site-packages\flask\app.py", line 1499, in dispatch_request
    return self.ensure_sync(self.view_functions[rule.endpoint])(**req.view_args)
  File "d:\term\python_learn\microblog\venv\lib\site-packages\flask_login\utils.py", line 272, in decorated_view
    return func(*args, **kwargs)
  File "D:\Term\python_learn\microblog\app\main\routes.py", line 148, in search
    posts, total = Post.search(g.search_form.q.data, page,
  File "D:\Term\python_learn\microblog\app\models.py", line 15, in search
    ids, total = query_index(cls.__tablename__, expression, page, per_page)
  File "D:\Term\python_learn\microblog\app\search.py", line 22, in query_index
    search = current_app.elasticsearch.search(
  File "d:\term\python_learn\microblog\venv\lib\site-packages\elasticsearch\client\utils.py", line 168, in _wrapped
    return func(*args, params=params, headers=headers, **kwargs)
  File "d:\term\python_learn\microblog\venv\lib\site-packages\elasticsearch\client\__init__.py", line 1668, in search
    return self.transport.perform_request(
  File "d:\term\python_learn\microblog\venv\lib\site-packages\elasticsearch\transport.py", line 409, in perform_request
    self._do_verify_elasticsearch(headers=headers, timeout=timeout)
  File "d:\term\python_learn\microblog\venv\lib\site-packages\elasticsearch\transport.py", line 598, in _do_verify_elasticsearch
    raise error
  File "d:\term\python_learn\microblog\venv\lib\site-packages\elasticsearch\transport.py", line 561, in _do_verify_elasticsearch
    _, info_headers, info_response = conn.perform_request(
  File "d:\term\python_learn\microblog\venv\lib\site-packages\elasticsearch\connection\http_urllib3.py", line 266, in perform_request
    raise ConnectionError("N/A", str(e), e)
elasticsearch.exceptions.ConnectionError: ConnectionError(<urllib3.connection.HTTPConnection object at 0x00000224A25FCBE0>: Failed to establish a new connection: [WinError 10061] 由于目标计算机积极拒绝，无法连接。) caused by: NewConnectionError(<urllib3.connection.HTTPConnection object at 0x00000224A25FCBE0>: Failed to establish a new connection: [WinError 10061] 由于目标计算机积极拒绝，无法连接。)
2021-08-05 15:39:09,088 INFO: Microblog startup [in D:\Term\python_learn\microblog\app\__init__.py:77]
